Workbook

Sheet LUNES 15
B1: =B155 -> 46188
B2: VENTA PUBLICO
B3: PRODUCTO | C3: $ COMPRA | D3: $ VENTA | E3: CANT | F3: $ | G3: CORTESIAS | I3: PRODUCTO | M3: $ COMPRA | N3: $ VENTA | O3: CANT | P3: $ | Q3: CORTESIAS
B4: MEDIA LAGER | C4: 15 | D4: 30 | F4: =E4*D4 -> 0 | H4: =G4*C4 -> 0 | I4: CIGARRO | M4: 6 | N4: 10 | P4: =O4*N4 -> 0
B5: MEDIA AZUL | C5: 14 | D5: 30 | F5: =E5*D5 -> 0 | H5: =G5*C5 -> 0 | I5: CACAHUATE | M5: 13 | N5: 25 | P5: =O5*N5 -> 0 | R5: =Q5*M5 -> 0
B6: MEDIA VICTORIA | C6: 17 | D6: 35 | F6: =E6*D6 -> 0 | H6: =G6*C6 -> 0 | I6: CHICARRON | M6: 11 | N6: 35 | P6: =O6*N6 -> 0 | R6: =Q6*M6 -> 0
B7: MEDIA CORONA | C7: 17 | D7: 35 | F7: =E7*D7 -> 0 | H7: =G7*C7 -> 0 | I7: SEMILLAS | M7: 10 | N7: 15 | P7: =O7*N7 -> 0 | R7: =Q7*M7 -> 0
B8: MEGA LAGER | C8: 37 | D8: 70 | F8: =E8*D8 -> 0 | H8: =G8*C8 -> 0 | I8: CANCION | M8: 0 | N8: 10 | P8: =O8*N8 -> 0 | R8: =Q8*M8 -> 0
B9: MEGA ROJA | C9: 35 | D9: 60 | F9: =E9*D9 -> 0 | H9: =G9*C9 -> 0 | I9: PAPAS | M9: 14.8 | N9: 35 | P9: =O9*N9 -> 0 | R9: =Q9*M9 -> 0
B10: MEGA AZUL | C10: 35 | D10: 60 | F10: =E10*D10 -> 0 | H10: =G10*C10 -> 0 | I10: COCA 355 | M10: 13 | N10: 20 | P10: =O10*N10 -> 0 | R10: =Q10*M10 -> 0
B11: MEGA VICTORIA | C11: 41 | D11: 80 | F11: =E11*D11 -> 0 | H11: =G11*C11 -> 0 | I11: PEÑAFIEL 355 | M11: 11 | N11: 20 | P11: =O11*N11 -> 0 | R11: =Q11*M11 -> 0
B12: MEGA CORONA | C12: 41 | D12: 80 | F12: =E12*D12 -> 0 | H12: =G12*C12 -> 0 | I12: TORONJA 355 | M12: 10 | N12: 20 | P12: =O12*N12 -> 0 | R12: =Q12*M12 -> 0
B13: CUBO MEDIA LAGER (6) | C13: =14*6 -> 84 | D13: 160 | F13: =E13*D13 -> 0 | I13: BOOS | M13: 40 | N13: 60 | P13: =O13*N13 -> 0
B14: CUBO MEDIA AZUL (6) | C14: =14*6 -> 84 | D14: 160 | F14: =E14*D14 -> 0 | I14: NEWMIX PALOMA | M14: 25 | N14: 45 | P14: =O14*N14 -> 0
B15: CUBO MEDIA VICTORIA (6) | C15: =17*6 -> 102 | D15: 180 | F15: =E15*D15 -> 0 | I15: NEWMIX VAMPIRO | M15: 25 | N15: 45 | P15: =O15*N15 -> 0
B16: CUBO MEDIA CORONA (6) | C16: =17*6 -> 102 | D16: 180 | F16: =E16*D16 -> 0 | I16: CLAMATO (Botella) | M16: 35 | N16: 50 | P16: =O16*N16 -> 0 | R16: =Q16*M16 -> 0
B17: PROMO MEGA LAGER (3) | C17: =37*3 -> 111 | D17: 195 | F17: =E17*D17 -> 0 | I17: CLAMATO (Preparado vaso) | M17: 27 | N17: 45 | P17: =O17*N17 -> 0 | R17: =Q17*M17 -> 0
B18: PROMO MEGA ROJA (3) | C18: =35*3 -> 105 | D18: 165 | F18: =E18*D18 -> 0 | I18: PREPARADO SALSAS (Vaso) | M18: 10 | N18: 25 | P18: =O18*N18 -> 0 | R18: =Q18*M18 -> 0
B19: PROMO MEGA AZUL (3) | C19: =35*3 -> 105 | D19: 165 | F19: =E19*D19 -> 0 | I19: SOPA | M19: 14 | N19: 35 | P19: =O19*N19 -> 0 | R19: =Q19*M19 -> 0
B20: PROMO MEGA VICTORIA (3) | C20: =41*3 -> 123 | D20: 225 | F20: =E20*D20 -> 0 | I20: BOTANA JAMON | M20: 40 | N20: 70 | P20: =O20*N20 -> 0 | R20: =Q20*M20 -> 0
B21: PROMO MEGA CORONA (3) | C21: =41*3 -> 123 | D21: 225 | F21: =E21*D21 -> 0 | I21: MANGUITO | M21: 8 | N21: 15 | P21: =O21*N21 -> 0 | R21: =Q21*M21 -> 0
B22: MICHE LAGER (2 MEDIAS) | C22: 40 | D22: 95 | F22: =E22*D22 -> 0 | I22: CHICLES | M22: 28 | N22: 50 | P22: =O22*N22 -> 0 | R22: =Q22*M22 -> 0
B23: MICHE AZUL (2 MEDIAS) | C23: 40 | D23: 95 | F23: =E23*D23 -> 0 | H23: =G23*C23 -> 0 | I23: DESCORCHE | N23: 300 | P23: =O23*N23 -> 0
B24: MICHE VICTORIA (2 MEDIAS) | C24: 45 | D24: 95 | F24: =E24*D24 -> 0 | H24: =G24*C24 -> 0 | I24: SALSA VALENTINA (CHICA) | M24: 17 | N24: 35 | P24: =O24*N24 -> 0 | R24: =Q24*M24 -> 0
B25: MICHE CORONA (2 MEDIAS) | C25: 45 | D25: 95 | F25: =E25*D25 -> 0 | H25: =G25*C25 -> 0 | I25: VASO ROTO | N25: 35 | P25: =O25*N25 -> 0
B26: COPA $50 | C26: 25 | D26: 50 | F26: =E26*D26 -> 0 | H26: =G26*C26 -> 0 | P26: =O26*N26 -> 0
B27: COPA $70 | C27: 30 | D27: 70 | F27: =E27*D27 -> 0 | H27: =G27*C27 -> 0 | P27: =O27*N27 -> 0
B28: COPA $100 | C28: 50 | D28: 100 | F28: =E28*D28 -> 0 | H28: =G28*C28 -> 0 | P28: =O28*N28 -> 0
B29: COPA $120 | C29: 70 | D29: 120 | F29: =E29*D29 -> 0 | H29: =G29*C29 -> 0 | P29: =O29*N29 -> 0
B30: COPA $150 | C30: 100 | D30: 150 | F30: =E30*D30 -> 0 | H30: =G30*C30 -> 0 | P30: =O30*N30 -> 0
B31: AZULITO | C31: 40 | D31: 95 | F31: =E31*D31 -> 0 | H31: =G31*C31 -> 0 | P31: =O31*N31 -> 0
B32: TOTAL DE VENTA | G32: =SUM(F4:F31,P4:P31) -> 0 | I32: TOTAL DE CORTESIAS | Q32: =SUM(H4:H31,R4:R31) -> 0
B34: =B155 -> 46188
B35: VENTA PERSONAL
B36: PRODUCTO | C36: $ COMPRA | D36: $ VENTA | E36: ELOY | G36: NUBIA | I36: MARCE | K36: ISELA | O36: VIKY | Q36: 4 | S36: 5 | U36: 6 | W36: 7
E37: CANT | F37: $ | G37: CANT | H37: $ | I37: CANT | J37: $ | K37: CANT | L37: $ | O37: CANT | P37: $ | Q37: CANT | R37: $ | S37: CANT | T37: $ | U37: CANT | V37: $ | W37: CANT | X37: $
B38: MEDIA LAGER | C38: 15 | D38: 30 | F38: =E38*C38 -> 0 | H38: =G38*C38 -> 0 | J38: =I38*C38 -> 0 | L38: =K38*C38 -> 0 | P38: =O38*C38 -> 0 | R38: =Q38*C38 -> 0 | T38: =S38*C38 -> 0 | V38: =U38*C38 -> 0 | X38: =W38*C38 -> 0
B39: MEDIA AZUL | C39: 14 | D39: 30 | F39: =E39*C39 -> 0 | H39: =G39*C39 -> 0 | J39: =I39*C39 -> 0 | L39: =K39*C39 -> 0 | P39: =O39*C39 -> 0 | R39: =Q39*C39 -> 0 | T39: =S39*C39 -> 0 | V39: =U39*C39 -> 0 | X39: =W39*C39 -> 0
B40: MEDIA VICTORIA | C40: 17 | D40: 35 | F40: =E40*C40 -> 0 | H40: =G40*C40 -> 0 | J40: =I40*C40 -> 0 | L40: =K40*C40 -> 0 | P40: =O40*C40 -> 0 | R40: =Q40*C40 -> 0 | T40: =S40*C40 -> 0 | V40: =U40*C40 -> 0 | X40: =W40*C40 -> 0
B41: MEDIA CORONA | C41: 17 | D41: 35 | F41: 1 | H41: =G41*C41 -> 0 | J41: =I41*C41 -> 0 | L41: =K41*C41 -> 0 | P41: =O41*C41 -> 0 | R41: =Q41*C41 -> 0 | T41: =S41*C41 -> 0 | V41: =U41*C41 -> 0 | X41: =W41*C41 -> 0
...

Sheet DOMINGO 14
B1: =B155 -> 46187
B2: VENTA PUBLICO
B3: PRODUCTO | C3: $ COMPRA | D3: $ VENTA | E3: CANT | F3: $ | G3: CORTESIAS | I3: PRODUCTO | M3: $ COMPRA | N3: $ VENTA | O3: CANT | P3: $ | Q3: CORTESIAS
B4: MEDIA LAGER | C4: 15 | D4: 30 | F4: =E4*D4 -> 0 | H4: =G4*C4 -> 0 | I4: CIGARRO | M4: 6 | N4: 10 | P4: =O4*N4 -> 0
B5: MEDIA AZUL | C5: 14 | D5: 30 | F5: =E5*D5 -> 0 | H5: =G5*C5 -> 0 | I5: CACAHUATE | M5: 13 | N5: 25 | P5: =O5*N5 -> 0 | R5: =Q5*M5 -> 0
B6: MEDIA VICTORIA | C6: 17 | D6: 35 | F6: =E6*D6 -> 0 | H6: =G6*C6 -> 0 | I6: CHICARRON | M6: 11 | N6: 35 | P6: =O6*N6 -> 0 | R6: =Q6*M6 -> 0
B7: MEDIA CORONA | C7: 17 | D7: 35 | F7: =E7*D7 -> 0 | H7: =G7*C7 -> 0 | I7: SEMILLAS | M7: 10 | N7: 15 | P7: =O7*N7 -> 0 | R7: =Q7*M7 -> 0
B8: MEGA LAGER | C8: 37 | D8: 70 | F8: =E8*D8 -> 0 | H8: =G8*C8 -> 0 | I8: CANCION | M8: 0 | N8: 10 | P8: =O8*N8 -> 0 | R8: =Q8*M8 -> 0
B9: MEGA ROJA | C9: 35 | D9: 60 | F9: =E9*D9 -> 0 | H9: =G9*C9 -> 0 | I9: PAPAS | M9: 14.8 | N9: 35 | P9: =O9*N9 -> 0 | R9: =Q9*M9 -> 0
B10: MEGA AZUL | C10: 35 | D10: 60 | F10: =E10*D10 -> 0 | H10: =G10*C10 -> 0 | I10: COCA 355 | M10: 13 | N10: 20 | P10: =O10*N10 -> 0 | R10: =Q10*M10 -> 0
B11: MEGA VICTORIA | C11: 41 | D11: 80 | F11: =E11*D11 -> 0 | H11: =G11*C11 -> 0 | I11: PEÑAFIEL 355 | M11: 11 | N11: 20 | P11: =O11*N11 -> 0 | R11: =Q11*M11 -> 0
B12: MEGA CORONA | C12: 41 | D12: 80 | F12: =E12*D12 -> 0 | H12: =G12*C12 -> 0 | I12: TORONJA 355 | M12: 10 | N12: 20 | P12: =O12*N12 -> 0 | R12: =Q12*M12 -> 0
B13: CUBO MEDIA LAGER (6) | C13: =14*6 -> 84 | D13: 160 | F13: =E13*D13 -> 0 | I13: BOOS | M13: 40 | N13: 60 | P13: =O13*N13 -> 0
B14: CUBO MEDIA AZUL (6) | C14: =14*6 -> 84 | D14: 160 | F14: =E14*D14 -> 0 | I14: NEWMIX PALOMA | M14: 25 | N14: 45 | P14: =O14*N14 -> 0
B15: CUBO MEDIA VICTORIA (6) | C15: =17*6 -> 102 | D15: 180 | F15: =E15*D15 -> 0 | I15: NEWMIX VAMPIRO | M15: 25 | N15: 45 | P15: =O15*N15 -> 0
B16: CUBO MEDIA CORONA (6) | C16: =17*6 -> 102 | D16: 180 | F16: =E16*D16 -> 0 | I16: CLAMATO (Botella) | M16: 35 | N16: 50 | P16: =O16*N16 -> 0 | R16: =Q16*M16 -> 0
B17: PROMO MEGA LAGER (3) | C17: =37*3 -> 111 | D17: 195 | F17: =E17*D17 -> 0 | I17: CLAMATO (Preparado vaso) | M17: 27 | N17: 45 | P17: =O17*N17 -> 0 | R17: =Q17*M17 -> 0
B18: PROMO MEGA ROJA (3) | C18: =35*3 -> 105 | D18: 165 | F18: =E18*D18 -> 0 | I18: PREPARADO SALSAS (Vaso) | M18: 10 | N18: 25 | P18: =O18*N18 -> 0 | R18: =Q18*M18 -> 0
B19: PROMO MEGA AZUL (3) | C19: =35*3 -> 105 | D19: 165 | F19: =E19*D19 -> 0 | I19: SOPA | M19: 14 | N19: 35 | P19: =O19*N19 -> 0 | R19: =Q19*M19 -> 0
B20: PROMO MEGA VICTORIA (3) | C20: =41*3 -> 123 | D20: 225 | F20: =E20*D20 -> 0 | I20: BOTANA JAMON | M20: 40 | N20: 70 | P20: =O20*N20 -> 0 | R20: =Q20*M20 -> 0
B21: PROMO MEGA CORONA (3) | C21: =41*3 -> 123 | D21: 225 | F21: =E21*D21 -> 0 | I21: MANGUITO | M21: 8 | N21: 15 | P21: =O21*N21 -> 0 | R21: =Q21*M21 -> 0
B22: MICHE LAGER (2 MEDIAS) | C22: 40 | D22: 95 | F22: =E22*D22 -> 0 | I22: CHICLES | M22: 28 | N22: 50 | P22: =O22*N22 -> 0 | R22: =Q22*M22 -> 0
B23: MICHE AZUL (2 MEDIAS) | C23: 40 | D23: 95 | F23: =E23*D23 -> 0 | H23: =G23*C23 -> 0 | I23: DESCORCHE | N23: 300 | P23: =O23*N23 -> 0
B24: MICHE VICTORIA (2 MEDIAS) | C24: 45 | D24: 95 | F24: =E24*D24 -> 0 | H24: =G24*C24 -> 0 | I24: SALSA VALENTINA (CHICA) | M24: 17 | N24: 35 | P24: =O24*N24 -> 0 | R24: =Q24*M24 -> 0
B25: MICHE CORONA (2 MEDIAS) | C25: 45 | D25: 95 | F25: =E25*D25 -> 0 | H25: =G25*C25 -> 0 | I25: VASO ROTO | N25: 35 | P25: =O25*N25 -> 0
B26: COPA $50 | C26: 25 | D26: 50 | F26: =E26*D26 -> 0 | H26: =G26*C26 -> 0 | P26: =O26*N26 -> 0
B27: COPA $70 | C27: 30 | D27: 70 | F27: =E27*D27 -> 0 | H27: =G27*C27 -> 0 | P27: =O27*N27 -> 0
B28: COPA $100 | C28: 50 | D28: 100 | F28: =E28*D28 -> 0 | H28: =G28*C28 -> 0 | P28: =O28*N28 -> 0
B29: COPA $120 | C29: 70 | D29: 120 | F29: =E29*D29 -> 0 | H29: =G29*C29 -> 0 | P29: =O29*N29 -> 0
B30: COPA $150 | C30: 100 | D30: 150 | F30: =E30*D30 -> 0 | H30: =G30*C30 -> 0 | P30: =O30*N30 -> 0
B31: AZULITO | C31: 40 | D31: 95 | F31: =E31*D31 -> 0 | H31: =G31*C31 -> 0 | P31: =O31*N31 -> 0
B32: TOTAL DE VENTA | G32: =SUM(F4:F31,P4:P31) -> 0 | I32: TOTAL DE CORTESIAS | Q32: =SUM(H4:H31,R4:R31) -> 0
B34: =B155 -> 46187
B35: VENTA PERSONAL
B36: PRODUCTO | C36: $ COMPRA | D36: $ VENTA | E36: ELOY | G36: NUBIA | I36: MARCE | K36: ISELA | O36: VIKY | Q36: 4 | S36: 5 | U36: 6 | W36: 7
E37: CANT | F37: $ | G37: CANT | H37: $ | I37: CANT | J37: $ | K37: CANT | L37: $ | O37: CANT | P37: $ | Q37: CANT | R37: $ | S37: CANT | T37: $ | U37: CANT | V37: $ | W37: CANT | X37: $
B38: MEDIA LAGER | C38: 15 | D38: 30 | F38: =E38*C38 -> 0 | H38: =G38*C38 -> 0 | J38: =I38*C38 -> 0 | L38: =K38*C38 -> 0 | P38: =O38*C38 -> 0 | R38: =Q38*C38 -> 0 | T38: =S38*C38 -> 0 | V38: =U38*C38 -> 0 | X38: =W38*C38 -> 0
B39: MEDIA AZUL | C39: 14 | D39: 30 | F39: =E39*C39 -> 0 | H39: =G39*C39 -> 0 | J39: =I39*C39 -> 0 | L39: =K39*C39 -> 0 | P39: =O39*C39 -> 0 | R39: =Q39*C39 -> 0 | T39: =S39*C39 -> 0 | V39: =U39*C39 -> 0 | X39: =W39*C39 -> 0
B40: MEDIA VICTORIA | C40: 17 | D40: 35 | F40: =E40*C40 -> 0 | H40: =G40*C40 -> 0 | J40: =I40*C40 -> 0 | L40: =K40*C40 -> 0 | P40: =O40*C40 -> 0 | R40: =Q40*C40 -> 0 | T40: =S40*C40 -> 0 | V40: =U40*C40 -> 0 | X40: =W40*C40 -> 0
B41: MEDIA CORONA | C41: 17 | D41: 35 | F41: 1 | H41: =G41*C41 -> 0 | J41: =I41*C41 -> 0 | L41: =K41*C41 -> 0 | P41: =O41*C41 -> 0 | R41: =Q41*C41 -> 0 | T41: =S41*C41 -> 0 | V41: =U41*C41 -> 0 | X41: =W41*C41 -> 0
...

Sheet SABADO 13
B1: =B155 -> 46185
B2: VENTA PUBLICO
B3: PRODUCTO | C3: $ COMPRA | D3: $ VENTA | E3: CANT | F3: $ | G3: CORTESIAS | I3: PRODUCTO | M3: $ COMPRA | N3: $ VENTA | O3: CANT | P3: $ | Q3: CORTESIAS
B4: MEDIA LAGER | C4: 15 | D4: 30 | F4: =E4*D4 -> 0 | H4: =G4*C4 -> 0 | I4: CIGARRO | M4: 6 | N4: 10 | P4: =O4*N4 -> 0
B5: MEDIA AZUL | C5: 14 | D5: 30 | F5: =E5*D5 -> 0 | H5: =G5*C5 -> 0 | I5: CACAHUATE | M5: 13 | N5: 25 | P5: =O5*N5 -> 0 | R5: =Q5*M5 -> 0
B6: MEDIA VICTORIA | C6: 17 | D6: 35 | F6: =E6*D6 -> 0 | H6: =G6*C6 -> 0 | I6: CHICARRON | M6: 11 | N6: 35 | P6: =O6*N6 -> 0 | R6: =Q6*M6 -> 0
B7: MEDIA CORONA | C7: 17 | D7: 35 | F7: =E7*D7 -> 0 | H7: =G7*C7 -> 0 | I7: SEMILLAS | M7: 10 | N7: 15 | P7: =O7*N7 -> 0 | R7: =Q7*M7 -> 0
B8: MEGA LAGER | C8: 37 | D8: 70 | F8: =E8*D8 -> 0 | H8: =G8*C8 -> 0 | I8: CANCION | M8: 0 | N8: 10 | P8: =O8*N8 -> 0 | R8: =Q8*M8 -> 0
B9: MEGA ROJA | C9: 35 | D9: 60 | F9: =E9*D9 -> 0 | H9: =G9*C9 -> 0 | I9: PAPAS | M9: 14.8 | N9: 35 | P9: =O9*N9 -> 0 | R9: =Q9*M9 -> 0
B10: MEGA AZUL | C10: 35 | D10: 60 | F10: =E10*D10 -> 0 | H10: =G10*C10 -> 0 | I10: COCA 355 | M10: 13 | N10: 20 | P10: =O10*N10 -> 0 | R10: =Q10*M10 -> 0
B11: MEGA VICTORIA | C11: 41 | D11: 80 | F11: =E11*D11 -> 0 | H11: =G11*C11 -> 0 | I11: PEÑAFIEL 355 | M11: 11 | N11: 20 | P11: =O11*N11 -> 0 | R11: =Q11*M11 -> 0
B12: MEGA CORONA | C12: 41 | D12: 80 | F12: =E12*D12 -> 0 | H12: =G12*C12 -> 0 | I12: TORONJA 355 | M12: 10 | N12: 20 | P12: =O12*N12 -> 0 | R12: =Q12*M12 -> 0
B13: CUBO MEDIA LAGER (6) | C13: =14*6 -> 84 | D13: 160 | F13: =E13*D13 -> 0 | I13: BOOS | M13: 40 | N13: 60 | P13: =O13*N13 -> 0
B14: CUBO MEDIA AZUL (6) | C14: =14*6 -> 84 | D14: 160 | F14: =E14*D14 -> 0 | I14: NEWMIX PALOMA | M14: 25 | N14: 45 | P14: =O14*N14 -> 0
B15: CUBO MEDIA VICTORIA (6) | C15: =17*6 -> 102 | D15: 180 | F15: =E15*D15 -> 0 | I15: NEWMIX VAMPIRO | M15: 25 | N15: 45 | P15: =O15*N15 -> 0
B16: CUBO MEDIA CORONA (6) | C16: =17*6 -> 102 | D16: 180 | F16: =E16*D16 -> 0 | I16: CLAMATO (Botella) | M16: 35 | N16: 50 | P16: =O16*N16 -> 0 | R16: =Q16*M16 -> 0
B17: PROMO MEGA LAGER (3) | C17: =37*3 -> 111 | D17: 195 | F17: =E17*D17 -> 0 | I17: CLAMATO (Preparado vaso) | M17: 27 | N17: 45 | P17: =O17*N17 -> 0 | R17: =Q17*M17 -> 0
B18: PROMO MEGA ROJA (3) | C18: =35*3 -> 105 | D18: 165 | F18: =E18*D18 -> 0 | I18: PREPARADO SALSAS (Vaso) | M18: 10 | N18: 25 | P18: =O18*N18 -> 0 | R18: =Q18*M18 -> 0
B19: PROMO MEGA AZUL (3) | C19: =35*3 -> 105 | D19: 165 | F19: =E19*D19 -> 0 | I19: SOPA | M19: 14 | N19: 35 | P19: =O19*N19 -> 0 | R19: =Q19*M19 -> 0
B20: PROMO MEGA VICTORIA (3) | C20: =41*3 -> 123 | D20: 225 | F20: =E20*D20 -> 0 | I20: BOTANA JAMON | M20: 40 | N20: 70 | P20: =O20*N20 -> 0 | R20: =Q20*M20 -> 0
B21: PROMO MEGA CORONA (3) | C21: =41*3 -> 123 | D21: 225 | F21: =E21*D21 -> 0 | I21: MANGUITO | M21: 8 | N21: 15 | P21: =O21*N21 -> 0 | R21: =Q21*M21 -> 0
B22: MICHE LAGER (2 MEDIAS) | C22: 40 | D22: 95 | F22: =E22*D22 -> 0 | I22: CHICLES | M22: 28 | N22: 50 | P22: =O22*N22 -> 0 | R22: =Q22*M22 -> 0
B23: MICHE AZUL (2 MEDIAS) | C23: 40 | D23: 95 | F23: =E23*D23 -> 0 | H23: =G23*C23 -> 0 | I23: DESCORCHE | N23: 300 | P23: =O23*N23 -> 0
B24: MICHE VICTORIA (2 MEDIAS) | C24: 45 | D24: 95 | F24: =E24*D24 -> 0 | H24: =G24*C24 -> 0 | I24: SALSA VALENTINA (CHICA) | M24: 17 | N24: 35 | P24: =O24*N24 -> 0 | R24: =Q24*M24 -> 0
B25: MICHE CORONA (2 MEDIAS) | C25: 45 | D25: 95 | F25: =E25*D25 -> 0 | H25: =G25*C25 -> 0 | I25: VASO ROTO | N25: 35 | P25: =O25*N25 -> 0
B26: COPA $50 | C26: 25 | D26: 50 | F26: =E26*D26 -> 0 | H26: =G26*C26 -> 0 | P26: =O26*N26 -> 0
B27: COPA $70 | C27: 30 | D27: 70 | F27: =E27*D27 -> 0 | H27: =G27*C27 -> 0 | P27: =O27*N27 -> 0
B28: COPA $100 | C28: 50 | D28: 100 | F28: =E28*D28 -> 0 | H28: =G28*C28 -> 0 | P28: =O28*N28 -> 0
B29: COPA $120 | C29: 70 | D29: 120 | F29: =E29*D29 -> 0 | H29: =G29*C29 -> 0 | P29: =O29*N29 -> 0
B30: COPA $150 | C30: 100 | D30: 150 | F30: =E30*D30 -> 0 | H30: =G30*C30 -> 0 | P30: =O30*N30 -> 0
B31: AZULITO | C31: 40 | D31: 95 | F31: =E31*D31 -> 0 | H31: =G31*C31 -> 0 | P31: =O31*N31 -> 0
B32: TOTAL DE VENTA | G32: =SUM(F4:F31,P4:P31) -> 0 | I32: TOTAL DE CORTESIAS | Q32: =SUM(H4:H31,R4:R31) -> 0
B34: =B155 -> 46185
B35: VENTA PERSONAL
B36: PRODUCTO | C36: $ COMPRA | D36: $ VENTA | E36: ELOY | G36: NUBIA | I36: MARCE | K36: ISELA | O36: VIKY | Q36: 4 | S36: 5 | U36: 6 | W36: 7
E37: CANT | F37: $ | G37: CANT | H37: $ | I37: CANT | J37: $ | K37: CANT | L37: $ | O37: CANT | P37: $ | Q37: CANT | R37: $ | S37: CANT | T37: $ | U37: CANT | V37: $ | W37: CANT | X37: $
B38: MEDIA LAGER | C38: 15 | D38: 30 | F38: =E38*C38 -> 0 | H38: =G38*C38 -> 0 | J38: =I38*C38 -> 0 | L38: =K38*C38 -> 0 | P38: =O38*C38 -> 0 | R38: =Q38*C38 -> 0 | T38: =S38*C38 -> 0 | V38: =U38*C38 -> 0 | X38: =W38*C38 -> 0
B39: MEDIA AZUL | C39: 14 | D39: 30 | F39: =E39*C39 -> 0 | H39: =G39*C39 -> 0 | J39: =I39*C39 -> 0 | L39: =K39*C39 -> 0 | P39: =O39*C39 -> 0 | R39: =Q39*C39 -> 0 | T39: =S39*C39 -> 0 | V39: =U39*C39 -> 0 | X39: =W39*C39 -> 0
B40: MEDIA VICTORIA | C40: 17 | D40: 35 | F40: =E40*C40 -> 0 | H40: =G40*C40 -> 0 | J40: =I40*C40 -> 0 | L40: =K40*C40 -> 0 | P40: =O40*C40 -> 0 | R40: =Q40*C40 -> 0 | T40: =S40*C40 -> 0 | V40: =U40*C40 -> 0 | X40: =W40*C40 -> 0
B41: MEDIA CORONA | C41: 17 | D41: 35 | F41: 1 | H41: =G41*C41 -> 0 | J41: =I41*C41 -> 0 | L41: =K41*C41 -> 0 | P41: =O41*C41 -> 0 | R41: =Q41*C41 -> 0 | T41: =S41*C41 -> 0 | V41: =U41*C41 -> 0 | X41: =W41*C41 -> 0
...

Sheet VIERNES 12
B1: =B155 -> 46185
B2: VENTA PUBLICO
B3: PRODUCTO | C3: $ COMPRA | D3: $ VENTA | E3: CANT | F3: $ | G3: CORTESIAS | I3: PRODUCTO | M3: $ COMPRA | N3: $ VENTA | O3: CANT | P3: $ | Q3: CORTESIAS
B4: MEDIA LAGER | C4: 15 | D4: 30 | F4: =E4*D4 -> 0 | H4: =G4*C4 -> 0 | I4: CIGARRO | M4: 6 | N4: 10 | P4: =O4*N4 -> 0
B5: MEDIA AZUL | C5: 14 | D5: 30 | F5: =E5*D5 -> 0 | H5: =G5*C5 -> 0 | I5: CACAHUATE | M5: 13 | N5: 25 | P5: =O5*N5 -> 0 | R5: =Q5*M5 -> 0
B6: MEDIA VICTORIA | C6: 17 | D6: 35 | F6: =E6*D6 -> 0 | H6: =G6*C6 -> 0 | I6: CHICARRON | M6: 11 | N6: 35 | P6: =O6*N6 -> 0 | R6: =Q6*M6 -> 0
B7: MEDIA CORONA | C7: 17 | D7: 35 | F7: =E7*D7 -> 0 | H7: =G7*C7 -> 0 | I7: SEMILLAS | M7: 10 | N7: 15 | P7: =O7*N7 -> 0 | R7: =Q7*M7 -> 0
B8: MEGA LAGER | C8: 37 | D8: 70 | F8: =E8*D8 -> 0 | H8: =G8*C8 -> 0 | I8: CANCION | M8: 0 | N8: 10 | P8: =O8*N8 -> 0 | R8: =Q8*M8 -> 0
B9: MEGA ROJA | C9: 35 | D9: 60 | F9: =E9*D9 -> 0 | H9: =G9*C9 -> 0 | I9: PAPAS | M9: 14.8 | N9: 35 | P9: =O9*N9 -> 0 | R9: =Q9*M9 -> 0
B10: MEGA AZUL | C10: 35 | D10: 60 | F10: =E10*D10 -> 0 | H10: =G10*C10 -> 0 | I10: COCA 355 | M10: 13 | N10: 20 | P10: =O10*N10 -> 0 | R10: =Q10*M10 -> 0
B11: MEGA VICTORIA | C11: 41 | D11: 80 | F11: =E11*D11 -> 0 | H11: =G11*C11 -> 0 | I11: PEÑAFIEL 355 | M11: 11 | N11: 20 | P11: =O11*N11 -> 0 | R11: =Q11*M11 -> 0
B12: MEGA CORONA | C12: 41 | D12: 80 | F12: =E12*D12 -> 0 | H12: =G12*C12 -> 0 | I12: TORONJA 355 | M12: 10 | N12: 20 | P12: =O12*N12 -> 0 | R12: =Q12*M12 -> 0
B13: CUBO MEDIA LAGER (6) | C13: =14*6 -> 84 | D13: 160 | F13: =E13*D13 -> 0 | I13: BOOS | M13: 40 | N13: 60 | P13: =O13*N13 -> 0
B14: CUBO MEDIA AZUL (6) | C14: =14*6 -> 84 | D14: 160 | F14: =E14*D14 -> 0 | I14: NEWMIX PALOMA | M14: 25 | N14: 45 | P14: =O14*N14 -> 0
B15: CUBO MEDIA VICTORIA (6) | C15: =17*6 -> 102 | D15: 180 | F15: =E15*D15 -> 0 | I15: NEWMIX VAMPIRO | M15: 25 | N15: 45 | P15: =O15*N15 -> 0
B16: CUBO MEDIA CORONA (6) | C16: =17*6 -> 102 | D16: 180 | F16: =E16*D16 -> 0 | I16: CLAMATO (Botella) | M16: 35 | N16: 50 | P16: =O16*N16 -> 0 | R16: =Q16*M16 -> 0
B17: PROMO MEGA LAGER (3) | C17: =37*3 -> 111 | D17: 195 | F17: =E17*D17 -> 0 | I17: CLAMATO (Preparado vaso) | M17: 27 | N17: 45 | P17: =O17*N17 -> 0 | R17: =Q17*M17 -> 0
B18: PROMO MEGA ROJA (3) | C18: =35*3 -> 105 | D18: 165 | F18: =E18*D18 -> 0 | I18: PREPARADO SALSAS (Vaso) | M18: 10 | N18: 25 | P18: =O18*N18 -> 0 | R18: =Q18*M18 -> 0
B19: PROMO MEGA AZUL (3) | C19: =35*3 -> 105 | D19: 165 | F19: =E19*D19 -> 0 | I19: SOPA | M19: 14 | N19: 35 | P19: =O19*N19 -> 0 | R19: =Q19*M19 -> 0
B20: PROMO MEGA VICTORIA (3) | C20: =41*3 -> 123 | D20: 225 | F20: =E20*D20 -> 0 | I20: BOTANA JAMON | M20: 40 | N20: 70 | P20: =O20*N20 -> 0 | R20: =Q20*M20 -> 0
B21: PROMO MEGA CORONA (3) | C21: =41*3 -> 123 | D21: 225 | F21: =E21*D21 -> 0 | I21: MANGUITO | M21: 8 | N21: 15 | P21: =O21*N21 -> 0 | R21: =Q21*M21 -> 0
B22: MICHE LAGER (2 MEDIAS) | C22: 40 | D22: 95 | F22: =E22*D22 -> 0 | I22: CHICLES | M22: 28 | N22: 50 | P22: =O22*N22 -> 0 | R22: =Q22*M22 -> 0
B23: MICHE AZUL (2 MEDIAS) | C23: 40 | D23: 95 | F23: =E23*D23 -> 0 | H23: =G23*C23 -> 0 | I23: DESCORCHE | N23: 300 | P23: =O23*N23 -> 0
B24: MICHE VICTORIA (2 MEDIAS) | C24: 45 | D24: 95 | F24: =E24*D24 -> 0 | H24: =G24*C24 -> 0 | I24: SALSA VALENTINA (CHICA) | M24: 17 | N24: 35 | P24: =O24*N24 -> 0 | R24: =Q24*M24 -> 0
B25: MICHE CORONA (2 MEDIAS) | C25: 45 | D25: 95 | F25: =E25*D25 -> 0 | H25: =G25*C25 -> 0 | I25: VASO ROTO | N25: 35 | P25: =O25*N25 -> 0
B26: COPA $50 | C26: 25 | D26: 50 | F26: =E26*D26 -> 0 | H26: =G26*C26 -> 0 | P26: =O26*N26 -> 0
B27: COPA $70 | C27: 30 | D27: 70 | F27: =E27*D27 -> 0 | H27: =G27*C27 -> 0 | P27: =O27*N27 -> 0
B28: COPA $100 | C28: 50 | D28: 100 | F28: =E28*D28 -> 0 | H28: =G28*C28 -> 0 | P28: =O28*N28 -> 0
B29: COPA $120 | C29: 70 | D29: 120 | F29: =E29*D29 -> 0 | H29: =G29*C29 -> 0 | P29: =O29*N29 -> 0
B30: COPA $150 | C30: 100 | D30: 150 | F30: =E30*D30 -> 0 | H30: =G30*C30 -> 0 | P30: =O30*N30 -> 0
B31: AZULITO | C31: 40 | D31: 95 | F31: =E31*D31 -> 0 | H31: =G31*C31 -> 0 | P31: =O31*N31 -> 0
B32: TOTAL DE VENTA | G32: =SUM(F4:F31,P4:P31) -> 0 | I32: TOTAL DE CORTESIAS | Q32: =SUM(H4:H31,R4:R31) -> 0
B34: =B155 -> 46185
B35: VENTA PERSONAL
B36: PRODUCTO | C36: $ COMPRA | D36: $ VENTA | E36: ELOY | G36: NUBIA | I36: MARCE | K36: ISELA | O36: VIKY | Q36: 4 | S36: 5 | U36: 6 | W36: 7
E37: CANT | F37: $ | G37: CANT | H37: $ | I37: CANT | J37: $ | K37: CANT | L37: $ | O37: CANT | P37: $ | Q37: CANT | R37: $ | S37: CANT | T37: $ | U37: CANT | V37: $ | W37: CANT | X37: $
B38: MEDIA LAGER | C38: 15 | D38: 30 | F38: =E38*C38 -> 0 | H38: =G38*C38 -> 0 | J38: =I38*C38 -> 0 | L38: =K38*C38 -> 0 | P38: =O38*C38 -> 0 | R38: =Q38*C38 -> 0 | T38: =S38*C38 -> 0 | V38: =U38*C38 -> 0 | X38: =W38*C38 -> 0
B39: MEDIA AZUL | C39: 14 | D39: 30 | F39: =E39*C39 -> 0 | H39: =G39*C39 -> 0 | J39: =I39*C39 -> 0 | L39: =K39*C39 -> 0 | P39: =O39*C39 -> 0 | R39: =Q39*C39 -> 0 | T39: =S39*C39 -> 0 | V39: =U39*C39 -> 0 | X39: =W39*C39 -> 0
B40: MEDIA VICTORIA | C40: 17 | D40: 35 | F40: =E40*C40 -> 0 | H40: =G40*C40 -> 0 | J40: =I40*C40 -> 0 | L40: =K40*C40 -> 0 | P40: =O40*C40 -> 0 | R40: =Q40*C40 -> 0 | T40: =S40*C40 -> 0 | V40: =U40*C40 -> 0 | X40: =W40*C40 -> 0
B41: MEDIA CORONA | C41: 17 | D41: 35 | F41: 1 | H41: =G41*C41 -> 0 | J41: =I41*C41 -> 0 | L41: =K41*C41 -> 0 | P41: =O41*C41 -> 0 | R41: =Q41*C41 -> 0 | T41: =S41*C41 -> 0 | V41: =U41*C41 -> 0 | X41: =W41*C41 -> 0
...

Sheet JUEVES 11
B1: =B155 -> 46184
B2: VENTA PUBLICO
B3: PRODUCTO | C3: $ COMPRA | D3: $ VENTA | E3: CANT | F3: $ | G3: CORTESIAS | I3: PRODUCTO | M3: $ COMPRA | N3: $ VENTA | O3: CANT | P3: $ | Q3: CORTESIAS
B4: MEDIA LAGER | C4: 15 | D4: 30 | E4: 9 | F4: =E4*D4 -> 270 | H4: =G4*C4 -> 0 | I4: CIGARRO | M4: 6 | N4: 10 | O4: 13 | P4: =O4*N4 -> 130
B5: MEDIA AZUL | C5: 14 | D5: 30 | F5: =E5*D5 -> 0 | H5: =G5*C5 -> 0 | I5: CACAHUATE | M5: 13 | N5: 25 | P5: =O5*N5 -> 0 | R5: =Q5*M5 -> 0
B6: MEDIA VICTORIA | C6: 17 | D6: 35 | F6: =E6*D6 -> 0 | G6: 2 | H6: =G6*C6 -> 34 | I6: CHICARRON | M6: 11 | N6: 35 | O6: 1 | P6: =O6*N6 -> 35 | R6: =Q6*M6 -> 0
B7: MEDIA CORONA | C7: 17 | D7: 35 | E7: 1 | F7: =E7*D7 -> 35 | H7: =G7*C7 -> 0 | I7: SEMILLAS | M7: 10 | N7: 15 | P7: =O7*N7 -> 0 | R7: =Q7*M7 -> 0
B8: MEGA LAGER | C8: 37 | D8: 70 | E8: 3 | F8: =E8*D8 -> 210 | G8: 3 | H8: =G8*C8 -> 111 | I8: CANCION | M8: 0 | N8: 10 | P8: =O8*N8 -> 0 | R8: =Q8*M8 -> 0
B9: MEGA ROJA | C9: 35 | D9: 60 | E9: 2 | F9: =E9*D9 -> 120 | H9: =G9*C9 -> 0 | I9: PAPAS | M9: 14.8 | N9: 35 | O9: 2 | P9: =O9*N9 -> 70 | R9: =Q9*M9 -> 0
B10: MEGA AZUL | C10: 35 | D10: 60 | E10: 4 | F10: =E10*D10 -> 240 | H10: =G10*C10 -> 0 | I10: COCA 355 | M10: 13 | N10: 20 | O10: 1 | P10: =O10*N10 -> 20 | R10: =Q10*M10 -> 0
B11: MEGA VICTORIA | C11: 41 | D11: 80 | F11: =E11*D11 -> 0 | H11: =G11*C11 -> 0 | I11: PEÑAFIEL 355 | M11: 11 | N11: 20 | P11: =O11*N11 -> 0 | R11: =Q11*M11 -> 0
B12: MEGA CORONA | C12: 41 | D12: 80 | F12: =E12*D12 -> 0 | H12: =G12*C12 -> 0 | I12: TORONJA 355 | M12: 10 | N12: 20 | P12: =O12*N12 -> 0 | R12: =Q12*M12 -> 0
B13: CUBO MEDIA LAGER (6) | C13: =14*6 -> 84 | D13: 160 | E13: 1 | F13: =E13*D13 -> 160 | I13: BOOS | M13: 40 | N13: 60 | P13: =O13*N13 -> 0
B14: CUBO MEDIA AZUL (6) | C14: =14*6 -> 84 | D14: 160 | F14: =E14*D14 -> 0 | I14: NEWMIX PALOMA | M14: 25 | N14: 45 | P14: =O14*N14 -> 0
B15: CUBO MEDIA VICTORIA (6) | C15: =17*6 -> 102 | D15: 180 | F15: =E15*D15 -> 0 | I15: NEWMIX VAMPIRO | M15: 25 | N15: 45 | P15: =O15*N15 -> 0
B16: CUBO MEDIA CORONA (6) | C16: =17*6 -> 102 | D16: 180 | F16: =E16*D16 -> 0 | I16: CLAMATO (Botella) | M16: 35 | N16: 50 | P16: =O16*N16 -> 0 | R16: =Q16*M16 -> 0
B17: PROMO MEGA LAGER (3) | C17: =37*3 -> 111 | D17: 195 | E17: 9 | F17: =E17*D17 -> 1755 | I17: CLAMATO (Preparado vaso) | M17: 27 | N17: 45 | P17: =O17*N17 -> 0 | R17: =Q17*M17 -> 0
B18: PROMO MEGA ROJA (3) | C18: =35*3 -> 105 | D18: 165 | E18: 3 | F18: =E18*D18 -> 495 | I18: PREPARADO SALSAS (Vaso) | M18: 10 | N18: 25 | P18: =O18*N18 -> 0 | R18: =Q18*M18 -> 0
B19: PROMO MEGA AZUL (3) | C19: =35*3 -> 105 | D19: 165 | E19: 1 | F19: =E19*D19 -> 165 | I19: SOPA | M19: 14 | N19: 35 | P19: =O19*N19 -> 0 | R19: =Q19*M19 -> 0
B20: PROMO MEGA VICTORIA (3) | C20: =41*3 -> 123 | D20: 225 | E20: 8 | F20: =E20*D20 -> 1800 | I20: BOTANA JAMON | M20: 40 | N20: 70 | P20: =O20*N20 -> 0 | R20: =Q20*M20 -> 0
B21: PROMO MEGA CORONA (3) | C21: =41*3 -> 123 | D21: 225 | F21: =E21*D21 -> 0 | I21: MANGUITO | M21: 8 | N21: 15 | P21: =O21*N21 -> 0 | R21: =Q21*M21 -> 0
B22: MICHE LAGER (2 MEDIAS) | C22: 40 | D22: 95 | F22: =E22*D22 -> 0 | I22: CHICLES | M22: 28 | N22: 50 | P22: =O22*N22 -> 0 | R22: =Q22*M22 -> 0
B23: MICHE AZUL (2 MEDIAS) | C23: 40 | D23: 95 | F23: =E23*D23 -> 0 | H23: =G23*C23 -> 0 | I23: DESCORCHE | N23: 300 | P23: =O23*N23 -> 0
B24: MICHE VICTORIA (2 MEDIAS) | C24: 45 | D24: 95 | F24: =E24*D24 -> 0 | H24: =G24*C24 -> 0 | I24: SALSA VALENTINA (CHICA) | M24: 17 | N24: 35 | P24: =O24*N24 -> 0 | R24: =Q24*M24 -> 0
B25: MICHE CORONA (2 MEDIAS) | C25: 45 | D25: 95 | F25: =E25*D25 -> 0 | H25: =G25*C25 -> 0 | I25: VASO ROTO | N25: 35 | P25: =O25*N25 -> 0
B26: COPA $50 | C26: 25 | D26: 50 | F26: =E26*D26 -> 0 | H26: =G26*C26 -> 0 | P26: =O26*N26 -> 0
B27: COPA $70 | C27: 30 | D27: 70 | F27: =E27*D27 -> 0 | H27: =G27*C27 -> 0 | P27: =O27*N27 -> 0
B28: COPA $100 | C28: 50 | D28: 100 | F28: =E28*D28 -> 0 | H28: =G28*C28 -> 0 | P28: =O28*N28 -> 0
B29: COPA $120 | C29: 70 | D29: 120 | F29: =E29*D29 -> 0 | H29: =G29*C29 -> 0 | P29: =O29*N29 -> 0
B30: COPA $150 | C30: 100 | D30: 150 | F30: =E30*D30 -> 0 | H30: =G30*C30 -> 0 | P30: =O30*N30 -> 0
B31: AZULITO | C31: 40 | D31: 95 | F31: =E31*D31 -> 0 | H31: =G31*C31 -> 0 | P31: =O31*N31 -> 0
B32: TOTAL DE VENTA | G32: =SUM(F4:F31,P4:P31) -> 5505 | I32: TOTAL DE CORTESIAS | Q32: =SUM(H4:H31,R4:R31) -> 145
B34: =B155 -> 46184
B35: VENTA PERSONAL
B36: PRODUCTO | C36: $ COMPRA | D36: $ VENTA | E36: ELOY | G36: NUBIA | I36: MARCE | K36: ISELA | O36: VIKY | Q36: 4 | S36: 5 | U36: 6 | W36: 7
E37: CANT | F37: $ | G37: CANT | H37: $ | I37: CANT | J37: $ | K37: CANT | L37: $ | O37: CANT | P37: $ | Q37: CANT | R37: $ | S37: CANT | T37: $ | U37: CANT | V37: $ | W37: CANT | X37: $
B38: MEDIA LAGER | C38: 15 | D38: 30 | E38: 2 | F38: =E38*C38 -> 30 | H38: =G38*C38 -> 0 | J38: =I38*C38 -> 0 | L38: =K38*C38 -> 0 | P38: =O38*C38 -> 0 | R38: =Q38*C38 -> 0 | T38: =S38*C38 -> 0 | V38: =U38*C38 -> 0 | X38: =W38*C38 -> 0
B39: MEDIA AZUL | C39: 14 | D39: 30 | F39: =E39*C39 -> 0 | H39: =G39*C39 -> 0 | J39: =I39*C39 -> 0 | K39: 1 | L39: =K39*C39 -> 14 | P39: =O39*C39 -> 0 | R39: =Q39*C39 -> 0 | T39: =S39*C39 -> 0 | V39: =U39*C39 -> 0 | X39: =W39*C39 -> 0
B40: MEDIA VICTORIA | C40: 17 | D40: 35 | F40: =E40*C40 -> 0 | H40: =G40*C40 -> 0 | J40: =I40*C40 -> 0 | L40: =K40*C40 -> 0 | P40: =O40*C40 -> 0 | R40: =Q40*C40 -> 0 | T40: =S40*C40 -> 0 | V40: =U40*C40 -> 0 | X40: =W40*C40 -> 0
B41: MEDIA CORONA | C41: 17 | D41: 35 | E41: 14 | F41: 1 | G41: 5 | H41: =G41*C41 -> 85 | J41: =I41*C41 -> 0 | L41: =K41*C41 -> 0 | P41: =O41*C41 -> 0 | R41: =Q41*C41 -> 0 | T41: =S41*C41 -> 0 | V41: =U41*C41 -> 0 | X41: =W41*C41 -> 0
...

Sheet MIERCOLES 10
B1: =B155 -> 46183
B2: VENTA PUBLICO
B3: PRODUCTO | C3: $ COMPRA | D3: $ VENTA | E3: CANT | F3: $ | G3: CORTESIAS | I3: PRODUCTO | M3: $ COMPRA | N3: $ VENTA | O3: CANT | P3: $ | Q3: CORTESIAS
B4: MEDIA LAGER | C4: 15 | D4: 30 | F4: =E4*D4 -> 0 | H4: =G4*C4 -> 0 | I4: CIGARRO | M4: 6 | N4: 10 | O4: 17 | P4: =O4*N4 -> 170
B5: MEDIA AZUL | C5: 14 | D5: 30 | F5: =E5*D5 -> 0 | H5: =G5*C5 -> 0 | I5: CACAHUATE | M5: 13 | N5: 25 | O5: 1 | P5: =O5*N5 -> 25 | R5: =Q5*M5 -> 0
B6: MEDIA VICTORIA | C6: 17 | D6: 35 | F6: =E6*D6 -> 0 | H6: =G6*C6 -> 0 | I6: CHICARRON | M6: 11 | N6: 35 | P6: =O6*N6 -> 0 | R6: =Q6*M6 -> 0
B7: MEDIA CORONA | C7: 17 | D7: 35 | E7: 1 | F7: =E7*D7 -> 35 | H7: =G7*C7 -> 0 | I7: SEMILLAS | M7: 10 | N7: 15 | P7: =O7*N7 -> 0 | R7: =Q7*M7 -> 0
B8: MEGA LAGER | C8: 37 | D8: 70 | E8: 2 | F8: =E8*D8 -> 140 | G8: 1 | H8: =G8*C8 -> 37 | I8: CANCION | M8: 0 | N8: 10 | O8: 3 | P8: =O8*N8 -> 30 | R8: =Q8*M8 -> 0
B9: MEGA ROJA | C9: 35 | D9: 60 | F9: =E9*D9 -> 0 | H9: =G9*C9 -> 0 | I9: PAPAS | M9: 14.8 | N9: 35 | P9: =O9*N9 -> 0 | R9: =Q9*M9 -> 0
B10: MEGA AZUL | C10: 35 | D10: 60 | E10: 1 | F10: =E10*D10 -> 60 | H10: =G10*C10 -> 0 | I10: COCA 355 | M10: 13 | N10: 20 | P10: =O10*N10 -> 0 | R10: =Q10*M10 -> 0
B11: MEGA VICTORIA | C11: 41 | D11: 80 | E11: 1 | F11: =E11*D11 -> 80 | H11: =G11*C11 -> 0 | I11: PEÑAFIEL 355 | M11: 11 | N11: 20 | P11: =O11*N11 -> 0 | R11: =Q11*M11 -> 0
B12: MEGA CORONA | C12: 41 | D12: 80 | E12: 1 | F12: =E12*D12 -> 80 | H12: =G12*C12 -> 0 | I12: TORONJA 355 | M12: 10 | N12: 20 | P12: =O12*N12 -> 0 | R12: =Q12*M12 -> 0
B13: CUBO MEDIA LAGER (6) | C13: =14*6 -> 84 | D13: 160 | F13: =E13*D13 -> 0 | I13: BOOS | M13: 40 | N13: 60 | P13: =O13*N13 -> 0
B14: CUBO MEDIA AZUL (6) | C14: =14*6 -> 84 | D14: 160 | F14: =E14*D14 -> 0 | I14: NEWMIX PALOMA | M14: 25 | N14: 45 | P14: =O14*N14 -> 0
B15: CUBO MEDIA VICTORIA (6) | C15: =17*6 -> 102 | D15: 180 | F15: =E15*D15 -> 0 | I15: NEWMIX VAMPIRO | M15: 25 | N15: 45 | P15: =O15*N15 -> 0
B16: CUBO MEDIA CORONA (6) | C16: =17*6 -> 102 | D16: 180 | F16: =E16*D16 -> 0 | I16: CLAMATO (Botella) | M16: 35 | N16: 50 | P16: =O16*N16 -> 0 | R16: =Q16*M16 -> 0
B17: PROMO MEGA LAGER (3) | C17: =37*3 -> 111 | D17: 195 | E17: 7 | F17: =E17*D17 -> 1365 | I17: CLAMATO (Preparado vaso) | M17: 27 | N17: 45 | P17: =O17*N17 -> 0 | R17: =Q17*M17 -> 0
B18: PROMO MEGA ROJA (3) | C18: =35*3 -> 105 | D18: 165 | E18: 3 | F18: =E18*D18 -> 495 | I18: PREPARADO SALSAS (Vaso) | M18: 10 | N18: 25 | P18: =O18*N18 -> 0 | R18: =Q18*M18 -> 0
B19: PROMO MEGA AZUL (3) | C19: =35*3 -> 105 | D19: 165 | E19: 1 | F19: =E19*D19 -> 165 | I19: SOPA | M19: 14 | N19: 35 | P19: =O19*N19 -> 0 | R19: =Q19*M19 -> 0
B20: PROMO MEGA VICTORIA (3) | C20: =41*3 -> 123 | D20: 225 | E20: 2 | F20: =E20*D20 -> 450 | I20: BOTANA JAMON | M20: 40 | N20: 70 | P20: =O20*N20 -> 0 | R20: =Q20*M20 -> 0
B21: PROMO MEGA CORONA (3) | C21: =41*3 -> 123 | D21: 225 | F21: =E21*D21 -> 0 | I21: MANGUITO | M21: 8 | N21: 15 | P21: =O21*N21 -> 0 | R21: =Q21*M21 -> 0
B22: MICHE LAGER (2 MEDIAS) | C22: 40 | D22: 95 | F22: =E22*D22 -> 0 | I22: CHICLES | M22: 28 | N22: 50 | P22: =O22*N22 -> 0 | R22: =Q22*M22 -> 0
B23: MICHE AZUL (2 MEDIAS) | C23: 40 | D23: 95 | F23: =E23*D23 -> 0 | H23: =G23*C23 -> 0 | I23: DESCORCHE | N23: 300 | P23: =O23*N23 -> 0
B24: MICHE VICTORIA (2 MEDIAS) | C24: 45 | D24: 95 | F24: =E24*D24 -> 0 | H24: =G24*C24 -> 0 | I24: SALSA VALENTINA (CHICA) | M24: 17 | N24: 35 | P24: =O24*N24 -> 0 | R24: =Q24*M24 -> 0
B25: MICHE CORONA (2 MEDIAS) | C25: 45 | D25: 95 | F25: =E25*D25 -> 0 | H25: =G25*C25 -> 0 | I25: VASO ROTO | N25: 35 | P25: =O25*N25 -> 0
B26: COPA $50 | C26: 25 | D26: 50 | F26: =E26*D26 -> 0 | H26: =G26*C26 -> 0 | P26: =O26*N26 -> 0
B27: COPA $70 | C27: 30 | D27: 70 | F27: =E27*D27 -> 0 | H27: =G27*C27 -> 0 | P27: =O27*N27 -> 0
B28: COPA $100 | C28: 50 | D28: 100 | F28: =E28*D28 -> 0 | H28: =G28*C28 -> 0 | P28: =O28*N28 -> 0
B29: COPA $120 | C29: 70 | D29: 120 | F29: =E29*D29 -> 0 | H29: =G29*C29 -> 0 | P29: =O29*N29 -> 0
B30: COPA $150 | C30: 100 | D30: 150 | F30: =E30*D30 -> 0 | H30: =G30*C30 -> 0 | P30: =O30*N30 -> 0
B31: AZULITO | C31: 40 | D31: 95 | F31: =E31*D31 -> 0 | H31: =G31*C31 -> 0 | P31: =O31*N31 -> 0
B32: TOTAL DE VENTA | G32: =SUM(F4:F31,P4:P31) -> 3095 | I32: TOTAL DE CORTESIAS | Q32: =SUM(H4:H31,R4:R31) -> 37
B34: =B155 -> 46183
B35: VENTA PERSONAL
B36: PRODUCTO | C36: $ COMPRA | D36: $ VENTA | E36: ELOY | G36: NUBIA | I36: MARCE | K36: ISELA | O36: VIKY | Q36: 4 | S36: 5 | U36: 6 | W36: 7
E37: CANT | F37: $ | G37: CANT | H37: $ | I37: CANT | J37: $ | K37: CANT | L37: $ | O37: CANT | P37: $ | Q37: CANT | R37: $ | S37: CANT | T37: $ | U37: CANT | V37: $ | W37: CANT | X37: $
B38: MEDIA LAGER | C38: 15 | D38: 30 | F38: =E38*C38 -> 0 | H38: =G38*C38 -> 0 | J38: =I38*C38 -> 0 | L38: =K38*C38 -> 0 | P38: =O38*C38 -> 0 | R38: =Q38*C38 -> 0 | T38: =S38*C38 -> 0 | V38: =U38*C38 -> 0 | X38: =W38*C38 -> 0
B39: MEDIA AZUL | C39: 14 | D39: 30 | F39: =E39*C39 -> 0 | H39: =G39*C39 -> 0 | J39: =I39*C39 -> 0 | L39: =K39*C39 -> 0 | P39: =O39*C39 -> 0 | R39: =Q39*C39 -> 0 | T39: =S39*C39 -> 0 | V39: =U39*C39 -> 0 | X39: =W39*C39 -> 0
B40: MEDIA VICTORIA | C40: 17 | D40: 35 | E40: 3 | F40: =E40*C40 -> 51 | H40: =G40*C40 -> 0 | J40: =I40*C40 -> 0 | L40: =K40*C40 -> 0 | P40: =O40*C40 -> 0 | R40: =Q40*C40 -> 0 | T40: =S40*C40 -> 0 | V40: =U40*C40 -> 0 | X40: =W40*C40 -> 0
B41: MEDIA CORONA | C41: 17 | D41: 35 | F41: 1 | H41: =G41*C41 -> 0 | J41: =I41*C41 -> 0 | L41: =K41*C41 -> 0 | P41: =O41*C41 -> 0 | R41: =Q41*C41 -> 0 | T41: =S41*C41 -> 0 | V41: =U41*C41 -> 0 | X41: =W41*C41 -> 0
...

Sheet MARTES 09
B1: =B155 -> 46182
B2: VENTA PUBLICO
B3: PRODUCTO | C3: $ COMPRA | D3: $ VENTA | E3: CANT | F3: $ | G3: CORTESIAS | I3: PRODUCTO | M3: $ COMPRA | N3: $ VENTA | O3: CANT | P3: $ | Q3: CORTESIAS
B4: MEDIA LAGER | C4: 15 | D4: 30 | F4: =E4*D4 -> 0 | H4: =G4*C4 -> 0 | I4: CIGARRO | M4: 6 | N4: 10 | O4: 4 | P4: =O4*N4 -> 40
B5: MEDIA AZUL | C5: 14 | D5: 30 | F5: =E5*D5 -> 0 | H5: =G5*C5 -> 0 | I5: CACAHUATE | M5: 13 | N5: 25 | O5: 1 | P5: =O5*N5 -> 25 | R5: =Q5*M5 -> 0
B6: MEDIA VICTORIA | C6: 17 | D6: 35 | F6: =E6*D6 -> 0 | H6: =G6*C6 -> 0 | I6: CHICARRON | M6: 11 | N6: 35 | P6: =O6*N6 -> 0 | R6: =Q6*M6 -> 0
B7: MEDIA CORONA | C7: 17 | D7: 35 | F7: =E7*D7 -> 0 | H7: =G7*C7 -> 0 | I7: SEMILLAS | M7: 10 | N7: 15 | P7: =O7*N7 -> 0 | R7: =Q7*M7 -> 0
B8: MEGA LAGER | C8: 37 | D8: 70 | E8: 2 | F8: =E8*D8 -> 140 | H8: =G8*C8 -> 0 | I8: CANCION | M8: 0 | N8: 10 | O8: 2 | P8: =O8*N8 -> 20 | R8: =Q8*M8 -> 0
B9: MEGA ROJA | C9: 35 | D9: 60 | E9: 1 | F9: =E9*D9 -> 60 | H9: =G9*C9 -> 0 | I9: PAPAS | M9: 14.8 | N9: 35 | P9: =O9*N9 -> 0 | R9: =Q9*M9 -> 0
B10: MEGA AZUL | C10: 35 | D10: 60 | E10: 2 | F10: =E10*D10 -> 120 | H10: =G10*C10 -> 0 | I10: COCA 355 | M10: 13 | N10: 20 | P10: =O10*N10 -> 0 | R10: =Q10*M10 -> 0
B11: MEGA VICTORIA | C11: 41 | D11: 80 | F11: =E11*D11 -> 0 | H11: =G11*C11 -> 0 | I11: PEÑAFIEL 355 | M11: 11 | N11: 20 | P11: =O11*N11 -> 0 | R11: =Q11*M11 -> 0
B12: MEGA CORONA | C12: 41 | D12: 80 | E12: 1 | F12: =E12*D12 -> 80 | H12: =G12*C12 -> 0 | I12: TORONJA 355 | M12: 10 | N12: 20 | P12: =O12*N12 -> 0 | R12: =Q12*M12 -> 0
B13: CUBO MEDIA LAGER (6) | C13: =14*6 -> 84 | D13: 160 | F13: =E13*D13 -> 0 | I13: BOOS | M13: 40 | N13: 60 | P13: =O13*N13 -> 0
B14: CUBO MEDIA AZUL (6) | C14: =14*6 -> 84 | D14: 160 | F14: =E14*D14 -> 0 | I14: NEWMIX PALOMA | M14: 25 | N14: 45 | P14: =O14*N14 -> 0
B15: CUBO MEDIA VICTORIA (6) | C15: =17*6 -> 102 | D15: 180 | F15: =E15*D15 -> 0 | I15: NEWMIX VAMPIRO | M15: 25 | N15: 45 | P15: =O15*N15 -> 0
B16: CUBO MEDIA CORONA (6) | C16: =17*6 -> 102 | D16: 180 | F16: =E16*D16 -> 0 | I16: CLAMATO (Botella) | M16: 35 | N16: 50 | P16: =O16*N16 -> 0 | R16: =Q16*M16 -> 0
B17: PROMO MEGA LAGER (3) | C17: =37*3 -> 111 | D17: 195 | E17: 7 | F17: =E17*D17 -> 1365 | I17: CLAMATO (Preparado vaso) | M17: 27 | N17: 45 | O17: 1 | P17: =O17*N17 -> 45 | R17: =Q17*M17 -> 0
B18: PROMO MEGA ROJA (3) | C18: =35*3 -> 105 | D18: 165 | E18: 5 | F18: =E18*D18 -> 825 | I18: PREPARADO SALSAS (Vaso) | M18: 10 | N18: 25 | P18: =O18*N18 -> 0 | R18: =Q18*M18 -> 0
B19: PROMO MEGA AZUL (3) | C19: =35*3 -> 105 | D19: 165 | E19: 2 | F19: =E19*D19 -> 330 | I19: SOPA | M19: 14 | N19: 35 | P19: =O19*N19 -> 0 | R19: =Q19*M19 -> 0
B20: PROMO MEGA VICTORIA (3) | C20: =41*3 -> 123 | D20: 225 | F20: =E20*D20 -> 0 | I20: BOTANA JAMON | M20: 40 | N20: 70 | P20: =O20*N20 -> 0 | R20: =Q20*M20 -> 0
B21: PROMO MEGA CORONA (3) | C21: =41*3 -> 123 | D21: 225 | F21: =E21*D21 -> 0 | I21: MANGUITO | M21: 8 | N21: 15 | P21: =O21*N21 -> 0 | R21: =Q21*M21 -> 0
B22: MICHE LAGER (2 MEDIAS) | C22: 40 | D22: 95 | F22: =E22*D22 -> 0 | I22: CHICLES | M22: 28 | N22: 50 | P22: =O22*N22 -> 0 | R22: =Q22*M22 -> 0
B23: MICHE AZUL (2 MEDIAS) | C23: 40 | D23: 95 | F23: =E23*D23 -> 0 | H23: =G23*C23 -> 0 | I23: DESCORCHE | N23: 300 | P23: =O23*N23 -> 0
B24: MICHE VICTORIA (2 MEDIAS) | C24: 45 | D24: 95 | F24: =E24*D24 -> 0 | H24: =G24*C24 -> 0 | I24: SALSA VALENTINA (CHICA) | M24: 17 | N24: 35 | P24: =O24*N24 -> 0 | R24: =Q24*M24 -> 0
B25: MICHE CORONA (2 MEDIAS) | C25: 45 | D25: 95 | F25: =E25*D25 -> 0 | H25: =G25*C25 -> 0 | I25: VASO ROTO | N25: 35 | P25: =O25*N25 -> 0
B26: COPA $50 | C26: 25 | D26: 50 | F26: =E26*D26 -> 0 | H26: =G26*C26 -> 0 | P26: =O26*N26 -> 0
B27: COPA $70 | C27: 30 | D27: 70 | F27: =E27*D27 -> 0 | H27: =G27*C27 -> 0 | P27: =O27*N27 -> 0
B28: COPA $100 | C28: 50 | D28: 100 | F28: =E28*D28 -> 0 | H28: =G28*C28 -> 0 | P28: =O28*N28 -> 0
B29: COPA $120 | C29: 70 | D29: 120 | F29: =E29*D29 -> 0 | H29: =G29*C29 -> 0 | P29: =O29*N29 -> 0
B30: COPA $150 | C30: 100 | D30: 150 | F30: =E30*D30 -> 0 | H30: =G30*C30 -> 0 | P30: =O30*N30 -> 0
B31: AZULITO | C31: 40 | D31: 95 | F31: =E31*D31 -> 0 | H31: =G31*C31 -> 0 | P31: =O31*N31 -> 0
B32: TOTAL DE VENTA | G32: =SUM(F4:F31,P4:P31) -> 3050 | I32: TOTAL DE CORTESIAS | Q32: =SUM(H4:H31,R4:R31) -> 0
B34: =B155 -> 46182
B35: VENTA PERSONAL
B36: PRODUCTO | C36: $ COMPRA | D36: $ VENTA | E36: ELOY | G36: NUBIA | I36: MARCE | K36: ISELA | O36: VIKY | Q36: 4 | S36: 5 | U36: 6 | W36: 7
E37: CANT | F37: $ | G37: CANT | H37: $ | I37: CANT | J37: $ | K37: CANT | L37: $ | O37: CANT | P37: $ | Q37: CANT | R37: $ | S37: CANT | T37: $ | U37: CANT | V37: $ | W37: CANT | X37: $
B38: MEDIA LAGER | C38: 15 | D38: 30 | F38: =E38*C38 -> 0 | H38: =G38*C38 -> 0 | J38: =I38*C38 -> 0 | L38: =K38*C38 -> 0 | P38: =O38*C38 -> 0 | R38: =Q38*C38 -> 0 | T38: =S38*C38 -> 0 | V38: =U38*C38 -> 0 | X38: =W38*C38 -> 0
B39: MEDIA AZUL | C39: 14 | D39: 30 | F39: =E39*C39 -> 0 | H39: =G39*C39 -> 0 | J39: =I39*C39 -> 0 | L39: =K39*C39 -> 0 | P39: =O39*C39 -> 0 | R39: =Q39*C39 -> 0 | T39: =S39*C39 -> 0 | V39: =U39*C39 -> 0 | X39: =W39*C39 -> 0
B40: MEDIA VICTORIA | C40: 17 | D40: 35 | E40: 9 | F40: =E40*C40 -> 153 | H40: =G40*C40 -> 0 | J40: =I40*C40 -> 0 | L40: =K40*C40 -> 0 | P40: =O40*C40 -> 0 | R40: =Q40*C40 -> 0 | T40: =S40*C40 -> 0 | V40: =U40*C40 -> 0 | X40: =W40*C40 -> 0
B41: MEDIA CORONA | C41: 17 | D41: 35 | F41: 1 | H41: =G41*C41 -> 0 | J41: =I41*C41 -> 0 | L41: =K41*C41 -> 0 | P41: =O41*C41 -> 0 | R41: =Q41*C41 -> 0 | T41: =S41*C41 -> 0 | V41: =U41*C41 -> 0 | X41: =W41*C41 -> 0
...

Sheet LUNES 08
B1: =B155 -> 46181
B2: VENTA PUBLICO
B3: PRODUCTO | C3: $ COMPRA | D3: $ VENTA | E3: CANT | F3: $ | G3: CORTESIAS | I3: PRODUCTO | M3: $ COMPRA | N3: $ VENTA | O3: CANT | P3: $ | Q3: CORTESIAS
B4: MEDIA LAGER | C4: 15 | D4: 30 | E4: 1 | F4: =E4*D4 -> 30 | H4: =G4*C4 -> 0 | I4: CIGARRO | M4: 6 | N4: 10 | O4: 2 | P4: =O4*N4 -> 20
B5: MEDIA AZUL | C5: 14 | D5: 30 | F5: =E5*D5 -> 0 | H5: =G5*C5 -> 0 | I5: CACAHUATE | M5: 13 | N5: 25 | O5: 6 | P5: =O5*N5 -> 150 | R5: =Q5*M5 -> 0
B6: MEDIA VICTORIA | C6: 17 | D6: 35 | E6: 3 | F6: =E6*D6 -> 105 | H6: =G6*C6 -> 0 | I6: CHICARRON | M6: 11 | N6: 35 | P6: =O6*N6 -> 0 | R6: =Q6*M6 -> 0
B7: MEDIA CORONA | C7: 17 | D7: 35 | E7: 6 | F7: =E7*D7 -> 210 | H7: =G7*C7 -> 0 | I7: SEMILLAS | M7: 10 | N7: 15 | P7: =O7*N7 -> 0 | R7: =Q7*M7 -> 0
B8: MEGA LAGER | C8: 37 | D8: 70 | E8: 2 | F8: =E8*D8 -> 140 | H8: =G8*C8 -> 0 | I8: CANCION | M8: 0 | N8: 10 | P8: =O8*N8 -> 0 | R8: =Q8*M8 -> 0
B9: MEGA ROJA | C9: 35 | D9: 60 | E9: 2 | F9: =E9*D9 -> 120 | H9: =G9*C9 -> 0 | I9: PAPAS | M9: 14.8 | N9: 35 | P9: =O9*N9 -> 0 | R9: =Q9*M9 -> 0
B10: MEGA AZUL | C10: 35 | D10: 60 | E10: 1 | F10: =E10*D10 -> 60 | H10: =G10*C10 -> 0 | I10: COCA 355 | M10: 13 | N10: 20 | P10: =O10*N10 -> 0 | R10: =Q10*M10 -> 0
B11: MEGA VICTORIA | C11: 41 | D11: 80 | F11: =E11*D11 -> 0 | H11: =G11*C11 -> 0 | I11: PEÑAFIEL 355 | M11: 11 | N11: 20 | P11: =O11*N11 -> 0 | R11: =Q11*M11 -> 0
B12: MEGA CORONA | C12: 41 | D12: 80 | E12: 2 | F12: =E12*D12 -> 160 | H12: =G12*C12 -> 0 | I12: TORONJA 355 | M12: 10 | N12: 20 | P12: =O12*N12 -> 0 | R12: =Q12*M12 -> 0
B13: CUBO MEDIA LAGER (6) | C13: =14*6 -> 84 | D13: 160 | E13: 1 | F13: =E13*D13 -> 160 | I13: BOOS | M13: 40 | N13: 60 | P13: =O13*N13 -> 0
B14: CUBO MEDIA AZUL (6) | C14: =14*6 -> 84 | D14: 160 | F14: =E14*D14 -> 0 | I14: NEWMIX PALOMA | M14: 25 | N14: 45 | P14: =O14*N14 -> 0
B15: CUBO MEDIA VICTORIA (6) | C15: =17*6 -> 102 | D15: 180 | E15: 1 | F15: =E15*D15 -> 180 | I15: NEWMIX VAMPIRO | M15: 25 | N15: 45 | P15: =O15*N15 -> 0
B16: CUBO MEDIA CORONA (6) | C16: =17*6 -> 102 | D16: 180 | F16: =E16*D16 -> 0 | I16: CLAMATO (Botella) | M16: 35 | N16: 50 | O16: 1 | P16: =O16*N16 -> 50 | R16: =Q16*M16 -> 0
B17: PROMO MEGA LAGER (3) | C17: =37*3 -> 111 | D17: 195 | F17: =E17*D17 -> 0 | I17: CLAMATO (Preparado vaso) | M17: 27 | N17: 45 | P17: =O17*N17 -> 0 | R17: =Q17*M17 -> 0
B18: PROMO MEGA ROJA (3) | C18: =35*3 -> 105 | D18: 165 | E18: 1 | F18: =E18*D18 -> 165 | I18: PREPARADO SALSAS (Vaso) | M18: 10 | N18: 25 | P18: =O18*N18 -> 0 | R18: =Q18*M18 -> 0
B19: PROMO MEGA AZUL (3) | C19: =35*3 -> 105 | D19: 165 | F19: =E19*D19 -> 0 | I19: SOPA | M19: 14 | N19: 35 | P19: =O19*N19 -> 0 | R19: =Q19*M19 -> 0
B20: PROMO MEGA VICTORIA (3) | C20: =41*3 -> 123 | D20: 225 | F20: =E20*D20 -> 0 | I20: BOTANA JAMON | M20: 40 | N20: 70 | P20: =O20*N20 -> 0 | R20: =Q20*M20 -> 0
B21: PROMO MEGA CORONA (3) | C21: =41*3 -> 123 | D21: 225 | E21: 2 | F21: =E21*D21 -> 450 | I21: MANGUITO | M21: 8 | N21: 15 | P21: =O21*N21 -> 0 | R21: =Q21*M21 -> 0
B22: MICHE LAGER (2 MEDIAS) | C22: 40 | D22: 95 | F22: =E22*D22 -> 0 | I22: CHICLES | M22: 28 | N22: 50 | P22: =O22*N22 -> 0 | R22: =Q22*M22 -> 0
B23: MICHE AZUL (2 MEDIAS) | C23: 40 | D23: 95 | F23: =E23*D23 -> 0 | H23: =G23*C23 -> 0 | I23: DESCORCHE | N23: 300 | P23: =O23*N23 -> 0
B24: MICHE VICTORIA (2 MEDIAS) | C24: 45 | D24: 95 | F24: =E24*D24 -> 0 | H24: =G24*C24 -> 0 | I24: SALSA VALENTINA (CHICA) | M24: 17 | N24: 35 | P24: =O24*N24 -> 0 | R24: =Q24*M24 -> 0
B25: MICHE CORONA (2 MEDIAS) | C25: 45 | D25: 95 | F25: =E25*D25 -> 0 | H25: =G25*C25 -> 0 | I25: VASO ROTO | N25: 35 | P25: =O25*N25 -> 0
B26: COPA $50 | C26: 25 | D26: 50 | F26: =E26*D26 -> 0 | H26: =G26*C26 -> 0 | P26: =O26*N26 -> 0
B27: COPA $70 | C27: 30 | D27: 70 | F27: =E27*D27 -> 0 | H27: =G27*C27 -> 0 | P27: =O27*N27 -> 0
B28: COPA $100 | C28: 50 | D28: 100 | F28: =E28*D28 -> 0 | H28: =G28*C28 -> 0 | P28: =O28*N28 -> 0
B29: COPA $120 | C29: 70 | D29: 120 | F29: =E29*D29 -> 0 | H29: =G29*C29 -> 0 | P29: =O29*N29 -> 0
B30: COPA $150 | C30: 100 | D30: 150 | F30: =E30*D30 -> 0 | H30: =G30*C30 -> 0 | P30: =O30*N30 -> 0
B31: AZULITO | C31: 40 | D31: 95 | F31: =E31*D31 -> 0 | H31: =G31*C31 -> 0 | P31: =O31*N31 -> 0
B32: TOTAL DE VENTA | G32: =SUM(F4:F31,P4:P31) -> 2000 | I32: TOTAL DE CORTESIAS | Q32: =SUM(H4:H31,R4:R31) -> 0
B34: =B155 -> 46181
B35: VENTA PERSONAL
B36: PRODUCTO | C36: $ COMPRA | D36: $ VENTA | E36: ELOY | G36: NUBIA | I36: MARCE | K36: ISELA | O36: VIKY | Q36: 4 | S36: 5 | U36: 6 | W36: 7
E37: CANT | F37: $ | G37: CANT | H37: $ | I37: CANT | J37: $ | K37: CANT | L37: $ | O37: CANT | P37: $ | Q37: CANT | R37: $ | S37: CANT | T37: $ | U37: CANT | V37: $ | W37: CANT | X37: $
B38: MEDIA LAGER | C38: 15 | D38: 30 | F38: =E38*C38 -> 0 | H38: =G38*C38 -> 0 | J38: =I38*C38 -> 0 | L38: =K38*C38 -> 0 | P38: =O38*C38 -> 0 | R38: =Q38*C38 -> 0 | T38: =S38*C38 -> 0 | V38: =U38*C38 -> 0 | X38: =W38*C38 -> 0
B39: MEDIA AZUL | C39: 14 | D39: 30 | F39: =E39*C39 -> 0 | H39: =G39*C39 -> 0 | J39: =I39*C39 -> 0 | L39: =K39*C39 -> 0 | P39: =O39*C39 -> 0 | R39: =Q39*C39 -> 0 | T39: =S39*C39 -> 0 | V39: =U39*C39 -> 0 | X39: =W39*C39 -> 0
B40: MEDIA VICTORIA | C40: 17 | D40: 35 | E40: 6 | F40: =E40*C40 -> 102 | H40: =G40*C40 -> 0 | J40: =I40*C40 -> 0 | L40: =K40*C40 -> 0 | P40: =O40*C40 -> 0 | R40: =Q40*C40 -> 0 | T40: =S40*C40 -> 0 | V40: =U40*C40 -> 0 | X40: =W40*C40 -> 0
B41: MEDIA CORONA | C41: 17 | D41: 35 | F41: 1 | H41: =G41*C41 -> 0 | J41: =I41*C41 -> 0 | L41: =K41*C41 -> 0 | P41: =O41*C41 -> 0 | R41: =Q41*C41 -> 0 | T41: =S41*C41 -> 0 | V41: =U41*C41 -> 0 | X41: =W41*C41 -> 0
...

Sheet DOMINGO 07
B1: =B155 -> 46180
B2: VENTA PUBLICO
B3: PRODUCTO | C3: $ COMPRA | D3: $ VENTA | E3: CANT | F3: $ | G3: CORTESIAS | I3: PRODUCTO | M3: $ COMPRA | N3: $ VENTA | O3: CANT | P3: $ | Q3: CORTESIAS
B4: MEDIA LAGER | C4: 15 | D4: 30 | F4: =E4*D4 -> 0 | H4: =G4*C4 -> 0 | I4: CIGARRO | M4: 6 | N4: 10 | P4: =O4*N4 -> 0
B5: MEDIA AZUL | C5: 14 | D5: 30 | F5: =E5*D5 -> 0 | H5: =G5*C5 -> 0 | I5: CACAHUATE | M5: 13 | N5: 25 | P5: =O5*N5 -> 0 | R5: =Q5*M5 -> 0
B6: MEDIA VICTORIA | C6: 17 | D6: 35 | E6: 2 | F6: =E6*D6 -> 70 | H6: =G6*C6 -> 0 | I6: CHICARRON | M6: 11 | N6: 35 | P6: =O6*N6 -> 0 | R6: =Q6*M6 -> 0
B7: MEDIA CORONA | C7: 17 | D7: 35 | E7: 1 | F7: =E7*D7 -> 35 | H7: =G7*C7 -> 0 | I7: SEMILLAS | M7: 10 | N7: 15 | O7: 1 | P7: =O7*N7 -> 15 | R7: =Q7*M7 -> 0
B8: MEGA LAGER | C8: 37 | D8: 70 | E8: 5 | F8: =E8*D8 -> 350 | H8: =G8*C8 -> 0 | I8: CANCION | M8: 0 | N8: 10 | O8: 13 | P8: =O8*N8 -> 130 | R8: =Q8*M8 -> 0
B9: MEGA ROJA | C9: 35 | D9: 60 | E9: 11 | F9: =E9*D9 -> 660 | H9: =G9*C9 -> 0 | I9: PAPAS | M9: 14.8 | N9: 35 | P9: =O9*N9 -> 0 | R9: =Q9*M9 -> 0
B10: MEGA AZUL | C10: 35 | D10: 60 | F10: =E10*D10 -> 0 | H10: =G10*C10 -> 0 | I10: COCA 355 | M10: 13 | N10: 20 | P10: =O10*N10 -> 0 | R10: =Q10*M10 -> 0
B11: MEGA VICTORIA | C11: 41 | D11: 80 | E11: 5 | F11: =E11*D11 -> 400 | H11: =G11*C11 -> 0 | I11: PEÑAFIEL 355 | M11: 11 | N11: 20 | P11: =O11*N11 -> 0 | R11: =Q11*M11 -> 0
B12: MEGA CORONA | C12: 41 | D12: 80 | F12: =E12*D12 -> 0 | H12: =G12*C12 -> 0 | I12: TORONJA 355 | M12: 10 | N12: 20 | P12: =O12*N12 -> 0 | R12: =Q12*M12 -> 0
B13: CUBO MEDIA LAGER (6) | C13: =14*6 -> 84 | D13: 160 | F13: =E13*D13 -> 0 | I13: BOOS | M13: 40 | N13: 60 | P13: =O13*N13 -> 0
B14: CUBO MEDIA AZUL (6) | C14: =14*6 -> 84 | D14: 160 | F14: =E14*D14 -> 0 | I14: NEWMIX PALOMA | M14: 25 | N14: 45 | P14: =O14*N14 -> 0
B15: CUBO MEDIA VICTORIA (6) | C15: =17*6 -> 102 | D15: 180 | F15: =E15*D15 -> 0 | I15: NEWMIX VAMPIRO | M15: 25 | N15: 45 | P15: =O15*N15 -> 0
B16: CUBO MEDIA CORONA (6) | C16: =17*6 -> 102 | D16: 180 | F16: =E16*D16 -> 0 | I16: CLAMATO (Botella) | M16: 35 | N16: 50 | P16: =O16*N16 -> 0 | R16: =Q16*M16 -> 0
B17: PROMO MEGA LAGER (3) | C17: =37*3 -> 111 | D17: 195 | F17: =E17*D17 -> 0 | I17: CLAMATO (Preparado vaso) | M17: 27 | N17: 45 | P17: =O17*N17 -> 0 | R17: =Q17*M17 -> 0
B18: PROMO MEGA ROJA (3) | C18: =35*3 -> 105 | D18: 165 | F18: =E18*D18 -> 0 | I18: PREPARADO SALSAS (Vaso) | M18: 10 | N18: 25 | P18: =O18*N18 -> 0 | R18: =Q18*M18 -> 0
B19: PROMO MEGA AZUL (3) | C19: =35*3 -> 105 | D19: 165 | F19: =E19*D19 -> 0 | I19: SOPA | M19: 14 | N19: 35 | P19: =O19*N19 -> 0 | R19: =Q19*M19 -> 0
B20: PROMO MEGA VICTORIA (3) | C20: =41*3 -> 123 | D20: 225 | F20: =E20*D20 -> 0 | I20: BOTANA JAMON | M20: 40 | N20: 70 | P20: =O20*N20 -> 0 | R20: =Q20*M20 -> 0
B21: PROMO MEGA CORONA (3) | C21: =41*3 -> 123 | D21: 225 | F21: =E21*D21 -> 0 | I21: MANGUITO | M21: 8 | N21: 15 | P21: =O21*N21 -> 0 | R21: =Q21*M21 -> 0
B22: MICHE LAGER (2 MEDIAS) | C22: 40 | D22: 95 | F22: =E22*D22 -> 0 | I22: CHICLES | M22: 28 | N22: 50 | P22: =O22*N22 -> 0 | R22: =Q22*M22 -> 0
B23: MICHE AZUL (2 MEDIAS) | C23: 40 | D23: 95 | F23: =E23*D23 -> 0 | H23: =G23*C23 -> 0 | I23: DESCORCHE | N23: 300 | P23: =O23*N23 -> 0
B24: MICHE VICTORIA (2 MEDIAS) | C24: 45 | D24: 95 | F24: =E24*D24 -> 0 | H24: =G24*C24 -> 0 | I24: SALSA VALENTINA (CHICA) | M24: 17 | N24: 35 | P24: =O24*N24 -> 0 | R24: =Q24*M24 -> 0
B25: MICHE CORONA (2 MEDIAS) | C25: 45 | D25: 95 | F25: =E25*D25 -> 0 | H25: =G25*C25 -> 0 | I25: VASO ROTO | N25: 35 | P25: =O25*N25 -> 0
B26: COPA $50 | C26: 25 | D26: 50 | F26: =E26*D26 -> 0 | H26: =G26*C26 -> 0 | P26: =O26*N26 -> 0
B27: COPA $70 | C27: 30 | D27: 70 | F27: =E27*D27 -> 0 | H27: =G27*C27 -> 0 | P27: =O27*N27 -> 0
B28: COPA $100 | C28: 50 | D28: 100 | F28: =E28*D28 -> 0 | H28: =G28*C28 -> 0 | P28: =O28*N28 -> 0
B29: COPA $120 | C29: 70 | D29: 120 | F29: =E29*D29 -> 0 | H29: =G29*C29 -> 0 | P29: =O29*N29 -> 0
B30: COPA $150 | C30: 100 | D30: 150 | F30: =E30*D30 -> 0 | H30: =G30*C30 -> 0 | P30: =O30*N30 -> 0
B31: AZULITO | C31: 40 | D31: 95 | F31: =E31*D31 -> 0 | H31: =G31*C31 -> 0 | P31: =O31*N31 -> 0
B32: TOTAL DE VENTA | G32: =SUM(F4:F31,P4:P31) -> 1660 | I32: TOTAL DE CORTESIAS | Q32: =SUM(H4:H31,R4:R31) -> 0
B34: =B155 -> 46180
B35: VENTA PERSONAL
B36: PRODUCTO | C36: $ COMPRA | D36: $ VENTA | E36: ELOY | G36: NUBIA | I36: MARCE | K36: ISELA | O36: VIKY | Q36: 4 | S36: 5 | U36: 6 | W36: 7
E37: CANT | F37: $ | G37: CANT | H37: $ | I37: CANT | J37: $ | K37: CANT | L37: $ | O37: CANT | P37: $ | Q37: CANT | R37: $ | S37: CANT | T37: $ | U37: CANT | V37: $ | W37: CANT | X37: $
B38: MEDIA LAGER | C38: 15 | D38: 30 | F38: =E38*C38 -> 0 | H38: =G38*C38 -> 0 | J38: =I38*C38 -> 0 | L38: =K38*C38 -> 0 | P38: =O38*C38 -> 0 | R38: =Q38*C38 -> 0 | T38: =S38*C38 -> 0 | V38: =U38*C38 -> 0 | X38: =W38*C38 -> 0
B39: MEDIA AZUL | C39: 14 | D39: 30 | F39: =E39*C39 -> 0 | H39: =G39*C39 -> 0 | J39: =I39*C39 -> 0 | L39: =K39*C39 -> 0 | P39: =O39*C39 -> 0 | R39: =Q39*C39 -> 0 | T39: =S39*C39 -> 0 | V39: =U39*C39 -> 0 | X39: =W39*C39 -> 0
B40: MEDIA VICTORIA | C40: 17 | D40: 35 | E40: 8 | F40: =E40*C40 -> 136 | H40: =G40*C40 -> 0 | J40: =I40*C40 -> 0 | L40: =K40*C40 -> 0 | P40: =O40*C40 -> 0 | R40: =Q40*C40 -> 0 | T40: =S40*C40 -> 0 | V40: =U40*C40 -> 0 | X40: =W40*C40 -> 0
B41: MEDIA CORONA | C41: 17 | D41: 35 | F41: 1 | H41: =G41*C41 -> 0 | J41: =I41*C41 -> 0 | L41: =K41*C41 -> 0 | P41: =O41*C41 -> 0 | R41: =Q41*C41 -> 0 | T41: =S41*C41 -> 0 | V41: =U41*C41 -> 0 | X41: =W41*C41 -> 0
...
